<?xml version="1.0" encoding="utf-8"?><testsuite errors="1" failures="0" name="pytest" skipped="0" tests="1" time="1.379"><testcase classname="" file="tests/test_kannel_APIs/test_rel_all_pairs.py" name="tests.test_kannel_APIs.test_rel_all_pairs" time="0.000"><error message="collection failure">../../app/__init__.py:41: in &lt;module&gt;
    with open(&apos;config.yml&apos;, &apos;r&apos;) as yaml_file:
E   FileNotFoundError: [Errno 2] No such file or directory: &apos;config.yml&apos;

During handling of the above exception, another exception occurred:
test_rel_all_pairs.py:24: in &lt;module&gt;
    from tests._fixtures import *
&lt;frozen importlib._bootstrap&gt;:971: in _find_and_load
    ???
&lt;frozen importlib._bootstrap&gt;:955: in _find_and_load_unlocked
    ???
&lt;frozen importlib._bootstrap&gt;:656: in _load_unlocked
    ???
&lt;frozen importlib._bootstrap&gt;:626: in _load_backward_compatible
    ???
../../venv/lib/python3.6/site-packages/_pytest/assertion/rewrite.py:296: in load_module
    six.exec_(co, mod.__dict__)
../_fixtures.py:35: in &lt;module&gt;
    from tests._helpers import *
&lt;frozen importlib._bootstrap&gt;:971: in _find_and_load
    ???
&lt;frozen importlib._bootstrap&gt;:955: in _find_and_load_unlocked
    ???
&lt;frozen importlib._bootstrap&gt;:656: in _load_unlocked
    ???
&lt;frozen importlib._bootstrap&gt;:626: in _load_backward_compatible
    ???
../../venv/lib/python3.6/site-packages/_pytest/assertion/rewrite.py:296: in load_module
    six.exec_(co, mod.__dict__)
../_helpers.py:25: in &lt;module&gt;
    from app.api.v1.models.owner import Owner
../../app/__init__.py:46: in &lt;module&gt;
    sys.exit(1)
E   SystemExit: 1</error></testcase></testsuite>